Workbook

Sheet Dashboard
A1: Franchise Development — Strategic Dashboard
A2: EXECUTIVE LAYER · Live roll-up across all 1:1 trackers. Updated automatically — no duplicate data entry. (Open the file in Excel and allow recalculation for live values.)
A4: =COUNTIF(Projects!$H$5:$H$47,">0") -> 14 | C4: =COUNTIF(Projects!$I$5:$I$47,"In Progress") -> 9 | E4: =COUNTIF(Projects!$I$5:$I$47,"At Risk") -> 1 | G4: =COUNTIF(Projects!$I$5:$I$47,"Blocked") -> 1 | I4: =COUNTIF(Projects!$I$5:$I$47,"Complete") -> 1 | K4: =IFERROR(SUM('All Tasks'!$U$5:$U$404)/SUM('All Tasks'!$W$5:$W$404),0) -> 0.38142857
A5: Active Projects | C5: On Track | E5: At Risk | G5: Blocked | I5: Complete | K5: Avg % Complete
A7: =SUM('All Tasks'!$W$5:$W$404) -> 35 | C7: =SUM('All Tasks'!$R$5:$R$404) -> 1 | E7: =SUM('All Tasks'!$S$5:$S$404) -> 1 | G7: =COUNTIF(Projects!$I$5:$I$47,"Not Started") -> 2 | I7: =COUNTIF(Projects!$I$5:$I$47,"No Tasks Yet") -> 29 | K7: =10 -> 10
A8: Total Active Tasks | C8: Overdue Tasks | E8: Due in 7 Days | G8: Not Started | I8: No Tasks Yet | K8: Total People
A11: Status by Focus Area | I11: Workload by Individual
A12: Focus Area | B12: Tasks | C12: Complete | D12: In Progress | E12: Overdue | F12: % Complete | G12: Health | I12: Person | J12: Tasks | K12: Open | L12: Complete | M12: Overdue | N12: % Complete
A13: 1 – Unified Development System | B13: =SUMIFS('All Tasks'!$W$5:$W$404,'All Tasks'!$C$5:$C$404,$A13) -> 11 | C13: =COUNTIFS('All Tasks'!$C$5:$C$404,$A13,'All Tasks'!$I$5:$I$404,"Complete") -> 0 | D13: =COUNTIFS('All Tasks'!$C$5:$C$404,$A13,'All Tasks'!$I$5:$I$404,"In Progress") -> 11 | E13: =SUMIFS('All Tasks'!$R$5:$R$404,'All Tasks'!$C$5:$C$404,$A13) -> 1 | F13: =IFERROR(SUMIFS('All Tasks'!$U$5:$U$404,'All Tasks'!$C$5:$C$404,$A13)/SUMIFS('All Tasks'!$W$5:$W$404,'All Tasks'!$C$5:$C$404,$A13),"") -> 0.5 | G13: =IF(COUNTIFS(Projects!$B$5:$B$47,$A13,Projects!$O$5:$O$47,"R")>0,"R",IF(COUNTIFS(Projects!$B$5:$B$47,$A13,Projects!$O$5:$O$47,"Y")>0,"Y",IF($B13=0,"-","G"))) -> R | I13: Quick Chadwick | J13: =SUMIFS('All Tasks'!$W$5:$W$404,'All Tasks'!$Q$5:$Q$404,$I13) -> 10 | K13: =$J13-$L13 -> 8 | L13: =COUNTIFS('All Tasks'!$Q$5:$Q$404,$I13,'All Tasks'!$I$5:$I$404,"Complete") -> 2 | M13: =SUMIFS('All Tasks'!$R$5:$R$404,'All Tasks'!$Q$5:$Q$404,$I13) -> 0 | N13: =IFERROR(SUMIFS('All Tasks'!$U$5:$U$404,'All Tasks'!$Q$5:$Q$404,$I13)/$J13,"") -> 0.415
A14: 2 – Top-of-Funnel Lead Gen | B14: =SUMIFS('All Tasks'!$W$5:$W$404,'All Tasks'!$C$5:$C$404,$A14) -> 3 | C14: =COUNTIFS('All Tasks'!$C$5:$C$404,$A14,'All Tasks'!$I$5:$I$404,"Complete") -> 1 | D14: =COUNTIFS('All Tasks'!$C$5:$C$404,$A14,'All Tasks'!$I$5:$I$404,"In Progress") -> 2 | E14: =SUMIFS('All Tasks'!$R$5:$R$404,'All Tasks'!$C$5:$C$404,$A14) -> 0 | F14: =IFERROR(SUMIFS('All Tasks'!$U$5:$U$404,'All Tasks'!$C$5:$C$404,$A14)/SUMIFS('All Tasks'!$W$5:$W$404,'All Tasks'!$C$5:$C$404,$A14),"") -> 0.53333333 | G14: =IF(COUNTIFS(Projects!$B$5:$B$47,$A14,Projects!$O$5:$O$47,"R")>0,"R",IF(COUNTIFS(Projects!$B$5:$B$47,$A14,Projects!$O$5:$O$47,"Y")>0,"Y",IF($B14=0,"-","G"))) -> G | I14: MaryFran Anderson | J14: =SUMIFS('All Tasks'!$W$5:$W$404,'All Tasks'!$Q$5:$Q$404,$I14) -> 6 | K14: =$J14-$L14 -> 6 | L14: =COUNTIFS('All Tasks'!$Q$5:$Q$404,$I14,'All Tasks'!$I$5:$I$404,"Complete") -> 0 | M14: =SUMIFS('All Tasks'!$R$5:$R$404,'All Tasks'!$Q$5:$Q$404,$I14) -> 0 | N14: =IFERROR(SUMIFS('All Tasks'!$U$5:$U$404,'All Tasks'!$Q$5:$Q$404,$I14)/$J14,"") -> 0.25
A15: 3 – Broker Channel | B15: =SUMIFS('All Tasks'!$W$5:$W$404,'All Tasks'!$C$5:$C$404,$A15) -> 7 | C15: =COUNTIFS('All Tasks'!$C$5:$C$404,$A15,'All Tasks'!$I$5:$I$404,"Complete") -> 0 | D15: =COUNTIFS('All Tasks'!$C$5:$C$404,$A15,'All Tasks'!$I$5:$I$404,"In Progress") -> 4 | E15: =SUMIFS('All Tasks'!$R$5:$R$404,'All Tasks'!$C$5:$C$404,$A15) -> 0 | F15: =IFERROR(SUMIFS('All Tasks'!$U$5:$U$404,'All Tasks'!$C$5:$C$404,$A15)/SUMIFS('All Tasks'!$W$5:$W$404,'All Tasks'!$C$5:$C$404,$A15),"") -> 0.2 | G15: =IF(COUNTIFS(Projects!$B$5:$B$47,$A15,Projects!$O$5:$O$47,"R")>0,"R",IF(COUNTIFS(Projects!$B$5:$B$47,$A15,Projects!$O$5:$O$47,"Y")>0,"Y",IF($B15=0,"-","G"))) -> R | I15: Shane Mattingly | J15: =SUMIFS('All Tasks'!$W$5:$W$404,'All Tasks'!$Q$5:$Q$404,$I15) -> 7 | K15: =$J15-$L15 -> 7 | L15: =COUNTIFS('All Tasks'!$Q$5:$Q$404,$I15,'All Tasks'!$I$5:$I$404,"Complete") -> 0 | M15: =SUMIFS('All Tasks'!$R$5:$R$404,'All Tasks'!$Q$5:$Q$404,$I15) -> 1 | N15: =IFERROR(SUMIFS('All Tasks'!$U$5:$U$404,'All Tasks'!$Q$5:$Q$404,$I15)/$J15,"") -> 0.27142857
A16: 4 – Portfolio Brand Strategy | B16: =SUMIFS('All Tasks'!$W$5:$W$404,'All Tasks'!$C$5:$C$404,$A16) -> 2 | C16: =COUNTIFS('All Tasks'!$C$5:$C$404,$A16,'All Tasks'!$I$5:$I$404,"Complete") -> 0 | D16: =COUNTIFS('All Tasks'!$C$5:$C$404,$A16,'All Tasks'!$I$5:$I$404,"In Progress") -> 2 | E16: =SUMIFS('All Tasks'!$R$5:$R$404,'All Tasks'!$C$5:$C$404,$A16) -> 0 | F16: =IFERROR(SUMIFS('All Tasks'!$U$5:$U$404,'All Tasks'!$C$5:$C$404,$A16)/SUMIFS('All Tasks'!$W$5:$W$404,'All Tasks'!$C$5:$C$404,$A16),"") -> 0.25 | G16: =IF(COUNTIFS(Projects!$B$5:$B$47,$A16,Projects!$O$5:$O$47,"R")>0,"R",IF(COUNTIFS(Projects!$B$5:$B$47,$A16,Projects!$O$5:$O$47,"Y")>0,"Y",IF($B16=0,"-","G"))) -> G | I16: Leslie Toole | J16: =SUMIFS('All Tasks'!$W$5:$W$404,'All Tasks'!$Q$5:$Q$404,$I16) -> 1 | K16: =$J16-$L16 -> 1 | L16: =COUNTIFS('All Tasks'!$Q$5:$Q$404,$I16,'All Tasks'!$I$5:$I$404,"Complete") -> 0 | M16: =SUMIFS('All Tasks'!$R$5:$R$404,'All Tasks'!$Q$5:$Q$404,$I16) -> 0 | N16: =IFERROR(SUMIFS('All Tasks'!$U$5:$U$404,'All Tasks'!$Q$5:$Q$404,$I16)/$J16,"") -> 0.5
A17: 5 – Operational Infrastructure | B17: =SUMIFS('All Tasks'!$W$5:$W$404,'All Tasks'!$C$5:$C$404,$A17) -> 1 | C17: =COUNTIFS('All Tasks'!$C$5:$C$404,$A17,'All Tasks'!$I$5:$I$404,"Complete") -> 0 | D17: =COUNTIFS('All Tasks'!$C$5:$C$404,$A17,'All Tasks'!$I$5:$I$404,"In Progress") -> 0 | E17: =SUMIFS('All Tasks'!$R$5:$R$404,'All Tasks'!$C$5:$C$404,$A17) -> 0 | F17: =IFERROR(SUMIFS('All Tasks'!$U$5:$U$404,'All Tasks'!$C$5:$C$404,$A17)/SUMIFS('All Tasks'!$W$5:$W$404,'All Tasks'!$C$5:$C$404,$A17),"") -> 0 | G17: =IF(COUNTIFS(Projects!$B$5:$B$47,$A17,Projects!$O$5:$O$47,"R")>0,"R",IF(COUNTIFS(Projects!$B$5:$B$47,$A17,Projects!$O$5:$O$47,"Y")>0,"Y",IF($B17=0,"-","G"))) -> Y | I17: Leah Hanlon | J17: =SUMIFS('All Tasks'!$W$5:$W$404,'All Tasks'!$Q$5:$Q$404,$I17) -> 1 | K17: =$J17-$L17 -> 1 | L17: =COUNTIFS('All Tasks'!$Q$5:$Q$404,$I17,'All Tasks'!$I$5:$I$404,"Complete") -> 0 | M17: =SUMIFS('All Tasks'!$R$5:$R$404,'All Tasks'!$Q$5:$Q$404,$I17) -> 0 | N17: =IFERROR(SUMIFS('All Tasks'!$U$5:$U$404,'All Tasks'!$Q$5:$Q$404,$I17)/$J17,"") -> 0.5
A18: 6 – Automation & Content | B18: =SUMIFS('All Tasks'!$W$5:$W$404,'All Tasks'!$C$5:$C$404,$A18) -> 9 | C18: =COUNTIFS('All Tasks'!$C$5:$C$404,$A18,'All Tasks'!$I$5:$I$404,"Complete") -> 2 | D18: =COUNTIFS('All Tasks'!$C$5:$C$404,$A18,'All Tasks'!$I$5:$I$404,"In Progress") -> 5 | E18: =SUMIFS('All Tasks'!$R$5:$R$404,'All Tasks'!$C$5:$C$404,$A18) -> 0 | F18: =IFERROR(SUMIFS('All Tasks'!$U$5:$U$404,'All Tasks'!$C$5:$C$404,$A18)/SUMIFS('All Tasks'!$W$5:$W$404,'All Tasks'!$C$5:$C$404,$A18),"") -> 0.42777778 | G18: =IF(COUNTIFS(Projects!$B$5:$B$47,$A18,Projects!$O$5:$O$47,"R")>0,"R",IF(COUNTIFS(Projects!$B$5:$B$47,$A18,Projects!$O$5:$O$47,"Y")>0,"Y",IF($B18=0,"-","G"))) -> G | I18: Jamie Lavigne | J18: =SUMIFS('All Tasks'!$W$5:$W$404,'All Tasks'!$Q$5:$Q$404,$I18) -> 2 | K18: =$J18-$L18 -> 2 | L18: =COUNTIFS('All Tasks'!$Q$5:$Q$404,$I18,'All Tasks'!$I$5:$I$404,"Complete") -> 0 | M18: =SUMIFS('All Tasks'!$R$5:$R$404,'All Tasks'!$Q$5:$Q$404,$I18) -> 0 | N18: =IFERROR(SUMIFS('All Tasks'!$U$5:$U$404,'All Tasks'!$Q$5:$Q$404,$I18)/$J18,"") -> 0.5
A19: 7 – Operating Rhythm | B19: =SUMIFS('All Tasks'!$W$5:$W$404,'All Tasks'!$C$5:$C$404,$A19) -> 2 | C19: =COUNTIFS('All Tasks'!$C$5:$C$404,$A19,'All Tasks'!$I$5:$I$404,"Complete") -> 0 | D19: =COUNTIFS('All Tasks'!$C$5:$C$404,$A19,'All Tasks'!$I$5:$I$404,"In Progress") -> 2 | E19: =SUMIFS('All Tasks'!$R$5:$R$404,'All Tasks'!$C$5:$C$404,$A19) -> 0 | F19: =IFERROR(SUMIFS('All Tasks'!$U$5:$U$404,'All Tasks'!$C$5:$C$404,$A19)/SUMIFS('All Tasks'!$W$5:$W$404,'All Tasks'!$C$5:$C$404,$A19),"") -> 0.25 | G19: =IF(COUNTIFS(Projects!$B$5:$B$47,$A19,Projects!$O$5:$O$47,"R")>0,"R",IF(COUNTIFS(Projects!$B$5:$B$47,$A19,Projects!$O$5:$O$47,"Y")>0,"Y",IF($B19=0,"-","G"))) -> G | I19: Steve Griffith | J19: =SUMIFS('All Tasks'!$W$5:$W$404,'All Tasks'!$Q$5:$Q$404,$I19) -> 2 | K19: =$J19-$L19 -> 2 | L19: =COUNTIFS('All Tasks'!$Q$5:$Q$404,$I19,'All Tasks'!$I$5:$I$404,"Complete") -> 0 | M19: =SUMIFS('All Tasks'!$R$5:$R$404,'All Tasks'!$Q$5:$Q$404,$I19) -> 0 | N19: =IFERROR(SUMIFS('All Tasks'!$U$5:$U$404,'All Tasks'!$Q$5:$Q$404,$I19)/$J19,"") -> 0.35
A20: 8 – Talent Evaluation | B20: =SUMIFS('All Tasks'!$W$5:$W$404,'All Tasks'!$C$5:$C$404,$A20) -> 0 | C20: =COUNTIFS('All Tasks'!$C$5:$C$404,$A20,'All Tasks'!$I$5:$I$404,"Complete") -> 0 | D20: =COUNTIFS('All Tasks'!$C$5:$C$404,$A20,'All Tasks'!$I$5:$I$404,"In Progress") -> 0 | E20: =SUMIFS('All Tasks'!$R$5:$R$404,'All Tasks'!$C$5:$C$404,$A20) -> 0 | F20: =IFERROR(SUMIFS('All Tasks'!$U$5:$U$404,'All Tasks'!$C$5:$C$404,$A20)/SUMIFS('All Tasks'!$W$5:$W$404,'All Tasks'!$C$5:$C$404,$A20),"") | G20: =IF(COUNTIFS(Projects!$B$5:$B$47,$A20,Projects!$O$5:$O$47,"R")>0,"R",IF(COUNTIFS(Projects!$B$5:$B$47,$A20,Projects!$O$5:$O$47,"Y")>0,"Y",IF($B20=0,"-","G"))) -> - | I20: Matt Motyka | J20: =SUMIFS('All Tasks'!$W$5:$W$404,'All Tasks'!$Q$5:$Q$404,$I20) -> 2 | K20: =$J20-$L20 -> 2 | L20: =COUNTIFS('All Tasks'!$Q$5:$Q$404,$I20,'All Tasks'!$I$5:$I$404,"Complete") -> 0 | M20: =SUMIFS('All Tasks'!$R$5:$R$404,'All Tasks'!$Q$5:$Q$404,$I20) -> 0 | N20: =IFERROR(SUMIFS('All Tasks'!$U$5:$U$404,'All Tasks'!$Q$5:$Q$404,$I20)/$J20,"") -> 0.4
I21: Alvaro Leal | J21: =SUMIFS('All Tasks'!$W$5:$W$404,'All Tasks'!$Q$5:$Q$404,$I21) -> 3 | K21: =$J21-$L21 -> 2 | L21: =COUNTIFS('All Tasks'!$Q$5:$Q$404,$I21,'All Tasks'!$I$5:$I$404,"Complete") -> 1 | M21: =SUMIFS('All Tasks'!$R$5:$R$404,'All Tasks'!$Q$5:$Q$404,$I21) -> 0 | N21: =IFERROR(SUMIFS('All Tasks'!$U$5:$U$404,'All Tasks'!$Q$5:$Q$404,$I21)/$J21,"") -> 0.6
I22: Cassidy Ford | J22: =SUMIFS('All Tasks'!$W$5:$W$404,'All Tasks'!$Q$5:$Q$404,$I22) -> 1 | K22: =$J22-$L22 -> 1 | L22: =COUNTIFS('All Tasks'!$Q$5:$Q$404,$I22,'All Tasks'!$I$5:$I$404,"Complete") -> 0 | M22: =SUMIFS('All Tasks'!$R$5:$R$404,'All Tasks'!$Q$5:$Q$404,$I22) -> 0 | N22: =IFERROR(SUMIFS('All Tasks'!$U$5:$U$404,'All Tasks'!$Q$5:$Q$404,$I22)/$J22,"") -> 0.5
A25: Project Status Distribution
A26: In Progress | B26: =COUNTIF(Projects!$I$5:$I$47,"In Progress") -> 9
A27: At Risk | B27: =COUNTIF(Projects!$I$5:$I$47,"At Risk") -> 1
A28: Blocked | B28: =COUNTIF(Projects!$I$5:$I$47,"Blocked") -> 1
A29: Complete | B29: =COUNTIF(Projects!$I$5:$I$47,"Complete") -> 1
A30: Not Started | B30: =COUNTIF(Projects!$I$5:$I$47,"Not Started") -> 2
A31: No Tasks Yet | B31: =COUNTIF(Projects!$I$5:$I$47,"No Tasks Yet") -> 29

Sheet Strategic Plan
B1: CGO - Strategic Plan
B3: Plan includes 8 focus areas comprised of 44 total tactics to completion over the next 100 days.
B5: 1 | C5: Build a Unified Franchise Development System | F5: Proj ID | G5: Lead | H5: Other | I5: Timing | J5: Status | K5: Notes / Commentary | M5: Legend | N5: Notes
D6: 1 | E6: Implement standardized Mutual Evaluation Process (MEP) across all brands | F6: =HYPERLINK("#Projects!A2","P1-1") -> P1-1 | G6: Developers | H6: Dobelbower | I6: Short (90) | J6: G | K6: Current franchise development processes vary significantly by brand, creating inconsistent candidate experiences and reducing scalability. | M6: na | N6: not started
D7: 2 | E7: Standardize pipeline stages, definitions, and reporting in CRM | F7: =HYPERLINK("#Projects!A3","P1-2") -> P1-2 | G7: Mattingly/Ruhlig | H7: Dobelbower | I7: Short (90) | J7: G | K7: Inconsistent pipeline definitions and reporting currently limit forecasting accuracy and portfolio-level visibility. | M7: G | N7: started & on track
D8: 3 | E8: Implement DAP (Development Action Plan) timelines for all candidates | F8: =HYPERLINK("#Projects!A4","P1-3") -> P1-3 | G8: Developers | H8: Dobelbower | I8: Short (90) | J8: G | K8: Current candidate progression lacks consistent timelines and accountability, creating unnecessary delays and reduced closing certainty. | M8: Y | N8: resolving minor issues
D9: 4 | E9: Standardize MTTD structure (confirmation event, not sales event) | F9: =HYPERLINK("#Projects!A5","P1-4") -> P1-4 | G9: Developers | H9: Dobelbower | I9: Mid (180) | J9: na | K9: MTTD execution varies significantly by brand and should function as a confirmation milestone rather than a late-stage persuasion event. | M9: R | N9: off track / needs attention
D10: 5 | E10: Standardize lead qualification across brands (Lumin, SDR, etc.) | F10: =HYPERLINK("#Projects!A6","P1-5") -> P1-5 | G10: Mattingly/Ruhlig | H10: Dobelbower | I10: Short (90) | J10: na | K10: Qualification standards currently vary by brand, resulting in inconsistent lead quality and inefficient developer utilization.
D11: 6 | E11: Launch weekly portfolio-wide pipeline call (eliminate silos) | F11: =HYPERLINK("#Projects!A7","P1-6") -> P1-6 | G11: Developers | H11: Dobelbower | I11: Short (90) | J11: C | K11: Weekly Pipeline Review kicked off 5/5
B13: =+B5+1 -> 2 | C13: Rebuild Top-of-Funnel Lead Generation | F13: Proj ID | G13: Lead | H13: Other | I13: Timing | J13: Status | K13: Notes / Commentary
D14: 1 | E14: Centralize non-broker marketing under Chadwick | F14: =HYPERLINK("#Projects!A8","P2-1") -> P2-1 | G14: Chadwick | H14: Dobelbower | I14: Short (90) | J14: C | K14: Non-broker lead generation efforts are currently fragmented across brands and lack centralized strategic prioritzation.
D15: 2 | E15: Reallocate spend toward non-broker sourced channels | F15: =HYPERLINK("#Projects!A9","P2-2") -> P2-2 | G15: Thoma/Chadwick | H15: Dobelbower | I15: Short (90) | J15: na | K15: Marketing spend allocation is not consistently aligned with lead quality, conversion performance, or long-term scalability objectives.
D16: 3 | E16: Build video-first funnel | F16: =HYPERLINK("#Projects!A10","P2-3") -> P2-3 | G16: M. Anderson/Leal | H16: Dobelbower | I16: Short (90) | J16: G | K16: Video and automation create an opportunity to improve candidate education, consistency, and developer scalability across all brands.
D17: 4 | E17: Establish portfolio-level KPIs benchmarked against AFDR ratios | F17: =HYPERLINK("#Projects!A11","P2-4") -> P2-4 | G17: Mattingly | H17: Dobelbower | I17: Mid (180) | J17: na | K17: Portfolio-level KPIs are necessary to properly evaluate marketing efficiency, lead quality, and channel performance across brands.
D18: 5 | E18: Eliminate low-quality lead sources | F18: =HYPERLINK("#Projects!A12","P2-5") -> P2-5 | G18: Chadwick | H18: Dobelbower | I18: Short (90) | J18: na | K18: Certain lead sources currently produce volume without corresponding conversion performance or franchisee quality.
B20: =+B13+1 -> 3 | C20: Optimize Broker Channel Performance | F20: Proj ID | G20: Lead | H20: Other | I20: Timing | J20: Status | K20: Notes / Commentary
D21: 1 | E21: Assign MaryFran as broker channel owner | F21: =HYPERLINK("#Projects!A13","P3-1") -> P3-1 | G21: MF. Anderson | H21: Dobelbower | I21: Short (90) | J21: C | K21: Broker relationships currently lack centralized ownership and consistent management across the portfolio.
D22: 2 | E22: Route 100% of broker leads through CRM for centralized intake and visibility. | F22: =HYPERLINK("#Projects!A14","P3-2") -> P3-2 | G22: Mattingly | H22: Dobelbower | I22: Short (90) | J22: G | K22: Shared inboxes and inconsistent lead routing create missed opportunities and limited visibility into broker activity.
D23: 3 | E23: Implement rules-based lead distribution | F23: =HYPERLINK("#Projects!A15","P3-3") -> P3-3 | G23: Mattingly/Ruhlig | H23: Dobelbower | I23: Short (90) | J23: na | K23: Lead distribution should prioritize fairness, responsiveness, and performance while eliminating perception of uneven opportunity.
D24: 4 | E24: Enforce speed-to-lead SLAs | F24: =HYPERLINK("#Projects!A16","P3-4") -> P3-4 | G24: MF. Anderson | H24: Dobelbower | I24: Short (90) | J24: na | K24: Response speed remains one of the largest drivers of broker lead conversion and candidate engagement.
D25: 5 | E25: Segment Brokers into Tier 1/Tier 2/ Tier 3 | F25: =HYPERLINK("#Projects!A17","P3-5") -> P3-5 | G25: MF. Anderson | H25: Dobelbower | J25: na | K25: Not all broker relationships generate equal value, requiring prioritization based on production and lead quality.
D26: 6 | E26: Introduce performance-based lead weighting | F26: =HYPERLINK("#Projects!A18","P3-6") -> P3-6 | G26: Mattingly/Ruhlig | H26: Dobelbower | J26: na | K26: Lead distribution should reward execution and conversion performance while maintaining equitable opportunity across the team.
D27: 7 | E27: Build weekly broker channel performance reporting | F27: =HYPERLINK("#Projects!A19","P3-7") -> P3-7 | G27: Mattingly/Ruhlig | H27: Dobelbower | I27: Short (90) | J27: na | K27: Broker performance visibility is currently limited, making it difficult to optimize relationships and conversion performance.
B29: =+B20+1 -> 4 | C29: Execute Portfolio-Based Brand Strategy | F29: Proj ID | G29: Lead | H29: Other | I29: Timing | J29: Status | K29: Notes / Commentary
D30: 1 | E30: Position The Seals as a low-cost, high-whitespace growth brand | F30: =HYPERLINK("#Projects!A20","P4-1") -> P4-1 | G30: Anderson/Chadwick | H30: Dobelbower | I30: Short (90) | J30: G | K30: The Seals presents an opportunity for accelerated unit growth due to low investment requirements, recurring revenue characteristics, and significant whitespace availability.
D31: 2 | E31: Position 1-Tom as a flagship growth brand | F31: =HYPERLINK("#Projects!A21","P4-2") -> P4-2 | G31: Anderson/Chadwick | H31: Dobelbower | I31: Short (90) | J31: G | K31: 1-Tom possesses strong branding, broad market appeal, and favorable long-term scalability characteristics.
D32: 3 | E32: Align Kitchen Guard growth strategy with Strategic Accounts initiatives | F32: =HYPERLINK("#Projects!A22","P4-3") -> P4-3 | G32: Hatcher | H32: Dobelbower | I32: Long (270) | J32: G | K32: Kitchen Guard’s compliance-driven recurring revenue model aligns well with enterprise and Strategic Account positioning opportunities.
D33: 4 | E33: Reposition Prism as a multi-service platform opportunity | F33: =HYPERLINK("#Projects!A23","P4-4") -> P4-4 | G33: Anderson/Chadwick | H33: Dobelbower | I33: Short (90) | J33: G | K33: Prism’s multi-service structure creates an opportunity to increase average deal size and long-term franchisee value.
D34: 5 | E34: Maintain stable, quality-focused growth for U.S. Lawns | F34: =HYPERLINK("#Projects!A24","P4-5") -> P4-5 | G34: Steeves | H34: Dobelbower | I34: Short (90) | J34: G | K34: U.S. Lawns serves as a mature and stable portfolio brand with strong recognition and operational consistency.
D35: 6 | E35: Utilize Clintar as a selective strategic growth vehicle | F35: =HYPERLINK("#Projects!A25","P4-6") -> P4-6 | G35: Motyka | H35: Dobelbower | I35: Mid (180) | J35: G | K35: Clintar should be positioned toward experienced operators and strategic opportunities rather than high-volume franchise sales efforts.
D36: 7 | E36: Rebuild validation and franchisee confidence within MilliCare | F36: =HYPERLINK("#Projects!A26","P4-7") -> P4-7 | G36: Griffith/Weaver | H36: Dobelbower | I36: Long (270) | J36: na | K36: Long-term MilliCare growth requires improvement in franchisee sentiment, validation consistency, and economic confidence.
B38: =+B29+1 -> 5 | C38: Strengthen Operational Infrastructure & Visbility | F38: Proj ID | G38: Lead | H38: Other | I38: Timing | J38: Status | K38: Notes / Commentary
D39: 1 | E39: Replace shared territory check inboxes with CRM routing | F39: =HYPERLINK("#Projects!A27","P5-1") -> P5-1 | G39: Mattingly | H39: Dobelbower | I39: Short (90) | J39: na | K39: Shared territory check workflows currently create operational inefficiencies and inconsistent response times.
D40: 2 | E40: Implement territory check response SLA | F40: =HYPERLINK("#Projects!A28","P5-2") -> P5-2 | G40: MF. Anderson | H40: Dobelbower | I40: Short (90) | J40: G | K40: Fast and consistent response times are critical to broker experience and franchise sales momentum.
D41: 3 | E41: Standardize lead assignment and routing logic | F41: =HYPERLINK("#Projects!A29","P5-3") -> P5-3 | G41: Mattingly | H41: Dobelbower | I41: Short (90) | J41: na | K41: Lead routing should prioritize transparency, accountability, and operational consistency across brands.
D42: 4 | E42: Build centralized KPI dashboard and reporting visibility | F42: =HYPERLINK("#Projects!A30","P5-4") -> P5-4 | G42: Mattingly/Ruhlig | H42: Dobelbower | I42: Mid (180) | J42: na | K42: Leadership currently lacks consistent portfolio-wide visibility into funnel health and conversion trends.
D43: 5 | E43: Improve CRM adoption and reporting discipline | F43: =HYPERLINK("#Projects!A31","P5-5") -> P5-5 | G43: Developers | H43: Dobelbower/Mattingly | I43: Short (90) | J43: G | K43: Consistent CRM usage is required to improve forecasting accuracy and operational visibility.
C45: Leverage Automation & Content to Improve Scalability | F45: Proj ID | G45: Lead | H45: Other | I45: Timing | J45: Status | K45: Notes / Commentary
B46: 6 | D46: 1 | E46: Develop standardized brand overview videos | F46: =HYPERLINK("#Projects!A32","P6-1") -> P6-1 | G46: M Anderson/Leal | H46: Dobelbower | I46: Mid (180) | J46: G | K46: Standardized brand messaging improves candidate consistency and reduces repetitive developer workload.
D47: 2 | E47: Develop validation preparation and candidate education content | F47: =HYPERLINK("#Projects!A33","P6-2") -> P6-2 | G47: Dobelbower | H47: N/A | I47: Short (90) | J47: G | K47: Better-prepared candidates improve validation outcomes and increase overall process efficiency.
...

Sheet Projects
A1: Projects — Tactic Roll-Up (auto)
A2: AGGREGATION LAYER · One row per tactic. Status, %, risks and milestones roll up automatically from the 1:1 tabs. Run project reviews here or open the Project Review tab.
A4: Project ID | B4: Focus Area | C4: Project / Tactic Name | D4: Exec Owner | E4: Lead Owner | F4: Strategic Goal (why) | G4: Timing | H4: Tasks | I4: Current Status | J4: % Complete | K4: Overdue | L4: Blocked | M4: Key Risks | N4: Next Milestone | O4: Health | P4: Review
A5: P1-1 | B5: 1 – Unified Development System | C5: Implement standardized Mutual Evaluation Process (MEP) across all brands | D5: Dobelbower | E5: Developers | F5: Current franchise development processes vary significantly by brand, creating inconsistent candidate experiences and reducing scalability. | G5: Short (90) | H5: =COUNTIF('All Tasks'!$B$2:$B$404,$A5) -> 10 | I5: =IF($H5=0,"No Tasks Yet",IF($L5>0,"Blocked",IF($K5>0,"At Risk",IF($R5=$H5,"Complete",IF($S5>0,"In Progress","Not Started"))))) -> In Progress | J5: =IF($H5=0,"",ROUND(SUMIFS('All Tasks'!$U$2:$U$404,'All Tasks'!$B$2:$B$404,$A5)/$H5,2)) -> 0.5 | K5: =SUMIFS('All Tasks'!$R$2:$R$404,'All Tasks'!$B$2:$B$404,$A5) -> 0 | L5: =COUNTIFS('All Tasks'!$B$2:$B$404,$A5,'All Tasks'!$I$2:$I$404,"Blocked") -> 0 | M5: =IF($H5=0,"",IF($L5>0,$L5&" blocked / "&$K5&" overdue",IF($K5>0,$K5&" overdue task(s)",IF($T5>0,$T5&" roadblock(s) flagged","On track")))) -> On track | N5: =IFERROR(minifs('All Tasks'!$L$2:$L$404,'All Tasks'!$B$2:$B$404,$A5,'All Tasks'!$I$2:$I$404,"<>Complete",'All Tasks'!$L$2:$L$404,">"&(TODAY()-1)),"") | O5: =IF($H5=0,"",IF(OR($I5="Blocked",$I5="At Risk"),"R",IF(OR($I5="Complete",$I5="In Progress"),"G","Y"))) -> G | P5: =HYPERLINK("#'Project Review'!C3","Open") -> Open | R5: =COUNTIFS('All Tasks'!$B$2:$B$404,$A5,'All Tasks'!$I$2:$I$404,"Complete") -> 0 | S5: =COUNTIFS('All Tasks'!$B$2:$B$404,$A5,'All Tasks'!$I$2:$I$404,"In Progress")+COUNTIFS('All Tasks'!$B$2:$B$404,$A5,'All Tasks'!$I$2:$I$404,"Waiting on Someone") -> 10 | T5: =SUMIFS('All Tasks'!$V$2:$V$404,'All Tasks'!$B$2:$B$404,$A5) -> 0
A6: P1-2 | B6: 1 – Unified Development System | C6: Standardize pipeline stages, definitions, and reporting in CRM | D6: Dobelbower | E6: Mattingly/Ruhlig | F6: Inconsistent pipeline definitions and reporting currently limit forecasting accuracy and portfolio-level visibility. | G6: Short (90) | H6: =COUNTIF('All Tasks'!$B$2:$B$404,$A6) -> 1 | I6: =IF($H6=0,"No Tasks Yet",IF($L6>0,"Blocked",IF($K6>0,"At Risk",IF($R6=$H6,"Complete",IF($S6>0,"In Progress","Not Started"))))) -> At Risk | J6: =IF($H6=0,"",ROUND(SUMIFS('All Tasks'!$U$2:$U$404,'All Tasks'!$B$2:$B$404,$A6)/$H6,2)) -> 0.5 | K6: =SUMIFS('All Tasks'!$R$2:$R$404,'All Tasks'!$B$2:$B$404,$A6) -> 1 | L6: =COUNTIFS('All Tasks'!$B$2:$B$404,$A6,'All Tasks'!$I$2:$I$404,"Blocked") -> 0 | M6: =IF($H6=0,"",IF($L6>0,$L6&" blocked / "&$K6&" overdue",IF($K6>0,$K6&" overdue task(s)",IF($T6>0,$T6&" roadblock(s) flagged","On track")))) -> 1 overdue task(s) | N6: =IFERROR(minifs('All Tasks'!$L$2:$L$404,'All Tasks'!$B$2:$B$404,$A6,'All Tasks'!$I$2:$I$404,"<>Complete",'All Tasks'!$L$2:$L$404,">"&(TODAY()-1)),"") | O6: =IF($H6=0,"",IF(OR($I6="Blocked",$I6="At Risk"),"R",IF(OR($I6="Complete",$I6="In Progress"),"G","Y"))) -> R | P6: =HYPERLINK("#'Project Review'!C3","Open") -> Open | R6: =COUNTIFS('All Tasks'!$B$2:$B$404,$A6,'All Tasks'!$I$2:$I$404,"Complete") -> 0 | S6: =COUNTIFS('All Tasks'!$B$2:$B$404,$A6,'All Tasks'!$I$2:$I$404,"In Progress")+COUNTIFS('All Tasks'!$B$2:$B$404,$A6,'All Tasks'!$I$2:$I$404,"Waiting on Someone") -> 1 | T6: =SUMIFS('All Tasks'!$V$2:$V$404,'All Tasks'!$B$2:$B$404,$A6) -> 0
A7: P1-3 | B7: 1 – Unified Development System | C7: Implement DAP (Development Action Plan) timelines for all candidates | D7: Dobelbower | E7: Developers | F7: Current candidate progression lacks consistent timelines and accountability, creating unnecessary delays and reduced closing certainty. | G7: Short (90) | H7: =COUNTIF('All Tasks'!$B$2:$B$404,$A7) -> 0 | I7: =IF($H7=0,"No Tasks Yet",IF($L7>0,"Blocked",IF($K7>0,"At Risk",IF($R7=$H7,"Complete",IF($S7>0,"In Progress","Not Started"))))) -> No Tasks Yet | J7: =IF($H7=0,"",ROUND(SUMIFS('All Tasks'!$U$2:$U$404,'All Tasks'!$B$2:$B$404,$A7)/$H7,2)) | K7: =SUMIFS('All Tasks'!$R$2:$R$404,'All Tasks'!$B$2:$B$404,$A7) -> 0 | L7: =COUNTIFS('All Tasks'!$B$2:$B$404,$A7,'All Tasks'!$I$2:$I$404,"Blocked") -> 0 | M7: =IF($H7=0,"",IF($L7>0,$L7&" blocked / "&$K7&" overdue",IF($K7>0,$K7&" overdue task(s)",IF($T7>0,$T7&" roadblock(s) flagged","On track")))) | N7: =IFERROR(minifs('All Tasks'!$L$2:$L$404,'All Tasks'!$B$2:$B$404,$A7,'All Tasks'!$I$2:$I$404,"<>Complete",'All Tasks'!$L$2:$L$404,">"&(TODAY()-1)),"") | O7: =IF($H7=0,"",IF(OR($I7="Blocked",$I7="At Risk"),"R",IF(OR($I7="Complete",$I7="In Progress"),"G","Y"))) | P7: =HYPERLINK("#'Project Review'!C3","Open") -> Open | R7: =COUNTIFS('All Tasks'!$B$2:$B$404,$A7,'All Tasks'!$I$2:$I$404,"Complete") -> 0 | S7: =COUNTIFS('All Tasks'!$B$2:$B$404,$A7,'All Tasks'!$I$2:$I$404,"In Progress")+COUNTIFS('All Tasks'!$B$2:$B$404,$A7,'All Tasks'!$I$2:$I$404,"Waiting on Someone") -> 0 | T7: =SUMIFS('All Tasks'!$V$2:$V$404,'All Tasks'!$B$2:$B$404,$A7) -> 0
A8: P1-4 | B8: 1 – Unified Development System | C8: Standardize MTTD structure (confirmation event, not sales event) | D8: Dobelbower | E8: Developers | F8: MTTD execution varies significantly by brand and should function as a confirmation milestone rather than a late-stage persuasion event. | G8: Mid (180) | H8: =COUNTIF('All Tasks'!$B$2:$B$404,$A8) -> 0 | I8: =IF($H8=0,"No Tasks Yet",IF($L8>0,"Blocked",IF($K8>0,"At Risk",IF($R8=$H8,"Complete",IF($S8>0,"In Progress","Not Started"))))) -> No Tasks Yet | J8: =IF($H8=0,"",ROUND(SUMIFS('All Tasks'!$U$2:$U$404,'All Tasks'!$B$2:$B$404,$A8)/$H8,2)) | K8: =SUMIFS('All Tasks'!$R$2:$R$404,'All Tasks'!$B$2:$B$404,$A8) -> 0 | L8: =COUNTIFS('All Tasks'!$B$2:$B$404,$A8,'All Tasks'!$I$2:$I$404,"Blocked") -> 0 | M8: =IF($H8=0,"",IF($L8>0,$L8&" blocked / "&$K8&" overdue",IF($K8>0,$K8&" overdue task(s)",IF($T8>0,$T8&" roadblock(s) flagged","On track")))) | N8: =IFERROR(minifs('All Tasks'!$L$2:$L$404,'All Tasks'!$B$2:$B$404,$A8,'All Tasks'!$I$2:$I$404,"<>Complete",'All Tasks'!$L$2:$L$404,">"&(TODAY()-1)),"") | O8: =IF($H8=0,"",IF(OR($I8="Blocked",$I8="At Risk"),"R",IF(OR($I8="Complete",$I8="In Progress"),"G","Y"))) | P8: =HYPERLINK("#'Project Review'!C3","Open") -> Open | R8: =COUNTIFS('All Tasks'!$B$2:$B$404,$A8,'All Tasks'!$I$2:$I$404,"Complete") -> 0 | S8: =COUNTIFS('All Tasks'!$B$2:$B$404,$A8,'All Tasks'!$I$2:$I$404,"In Progress")+COUNTIFS('All Tasks'!$B$2:$B$404,$A8,'All Tasks'!$I$2:$I$404,"Waiting on Someone") -> 0 | T8: =SUMIFS('All Tasks'!$V$2:$V$404,'All Tasks'!$B$2:$B$404,$A8) -> 0
A9: P1-5 | B9: 1 – Unified Development System | C9: Standardize lead qualification across brands (Lumin, SDR, etc.) | D9: Dobelbower | E9: Mattingly/Ruhlig | F9: Qualification standards currently vary by brand, resulting in inconsistent lead quality and inefficient developer utilization. | G9: Short (90) | H9: =COUNTIF('All Tasks'!$B$2:$B$404,$A9) -> 0 | I9: =IF($H9=0,"No Tasks Yet",IF($L9>0,"Blocked",IF($K9>0,"At Risk",IF($R9=$H9,"Complete",IF($S9>0,"In Progress","Not Started"))))) -> No Tasks Yet | J9: =IF($H9=0,"",ROUND(SUMIFS('All Tasks'!$U$2:$U$404,'All Tasks'!$B$2:$B$404,$A9)/$H9,2)) | K9: =SUMIFS('All Tasks'!$R$2:$R$404,'All Tasks'!$B$2:$B$404,$A9) -> 0 | L9: =COUNTIFS('All Tasks'!$B$2:$B$404,$A9,'All Tasks'!$I$2:$I$404,"Blocked") -> 0 | M9: =IF($H9=0,"",IF($L9>0,$L9&" blocked / "&$K9&" overdue",IF($K9>0,$K9&" overdue task(s)",IF($T9>0,$T9&" roadblock(s) flagged","On track")))) | N9: =IFERROR(minifs('All Tasks'!$L$2:$L$404,'All Tasks'!$B$2:$B$404,$A9,'All Tasks'!$I$2:$I$404,"<>Complete",'All Tasks'!$L$2:$L$404,">"&(TODAY()-1)),"") | O9: =IF($H9=0,"",IF(OR($I9="Blocked",$I9="At Risk"),"R",IF(OR($I9="Complete",$I9="In Progress"),"G","Y"))) | P9: =HYPERLINK("#'Project Review'!C3","Open") -> Open | R9: =COUNTIFS('All Tasks'!$B$2:$B$404,$A9,'All Tasks'!$I$2:$I$404,"Complete") -> 0 | S9: =COUNTIFS('All Tasks'!$B$2:$B$404,$A9,'All Tasks'!$I$2:$I$404,"In Progress")+COUNTIFS('All Tasks'!$B$2:$B$404,$A9,'All Tasks'!$I$2:$I$404,"Waiting on Someone") -> 0 | T9: =SUMIFS('All Tasks'!$V$2:$V$404,'All Tasks'!$B$2:$B$404,$A9) -> 0
A10: P1-6 | B10: 1 – Unified Development System | C10: Launch weekly portfolio-wide pipeline call (eliminate silos) | D10: Dobelbower | E10: Developers | F10: Weekly Pipeline Review kicked off 5/5 | G10: Short (90) | H10: =COUNTIF('All Tasks'!$B$2:$B$404,$A10) -> 0 | I10: =IF($H10=0,"No Tasks Yet",IF($L10>0,"Blocked",IF($K10>0,"At Risk",IF($R10=$H10,"Complete",IF($S10>0,"In Progress","Not Started"))))) -> No Tasks Yet | J10: =IF($H10=0,"",ROUND(SUMIFS('All Tasks'!$U$2:$U$404,'All Tasks'!$B$2:$B$404,$A10)/$H10,2)) | K10: =SUMIFS('All Tasks'!$R$2:$R$404,'All Tasks'!$B$2:$B$404,$A10) -> 0 | L10: =COUNTIFS('All Tasks'!$B$2:$B$404,$A10,'All Tasks'!$I$2:$I$404,"Blocked") -> 0 | M10: =IF($H10=0,"",IF($L10>0,$L10&" blocked / "&$K10&" overdue",IF($K10>0,$K10&" overdue task(s)",IF($T10>0,$T10&" roadblock(s) flagged","On track")))) | N10: =IFERROR(minifs('All Tasks'!$L$2:$L$404,'All Tasks'!$B$2:$B$404,$A10,'All Tasks'!$I$2:$I$404,"<>Complete",'All Tasks'!$L$2:$L$404,">"&(TODAY()-1)),"") | O10: =IF($H10=0,"",IF(OR($I10="Blocked",$I10="At Risk"),"R",IF(OR($I10="Complete",$I10="In Progress"),"G","Y"))) | P10: =HYPERLINK("#'Project Review'!C3","Open") -> Open | R10: =COUNTIFS('All Tasks'!$B$2:$B$404,$A10,'All Tasks'!$I$2:$I$404,"Complete") -> 0 | S10: =COUNTIFS('All Tasks'!$B$2:$B$404,$A10,'All Tasks'!$I$2:$I$404,"In Progress")+COUNTIFS('All Tasks'!$B$2:$B$404,$A10,'All Tasks'!$I$2:$I$404,"Waiting on Someone") -> 0 | T10: =SUMIFS('All Tasks'!$V$2:$V$404,'All Tasks'!$B$2:$B$404,$A10) -> 0
A11: P2-1 | B11: 2 – Top-of-Funnel Lead Gen | C11: Centralize non-broker marketing under Chadwick | D11: Dobelbower | E11: Chadwick | F11: Non-broker lead generation efforts are currently fragmented across brands and lack centralized strategic prioritzation. | G11: Short (90) | H11: =COUNTIF('All Tasks'!$B$2:$B$404,$A11) -> 0 | I11: =IF($H11=0,"No Tasks Yet",IF($L11>0,"Blocked",IF($K11>0,"At Risk",IF($R11=$H11,"Complete",IF($S11>0,"In Progress","Not Started"))))) -> No Tasks Yet | J11: =IF($H11=0,"",ROUND(SUMIFS('All Tasks'!$U$2:$U$404,'All Tasks'!$B$2:$B$404,$A11)/$H11,2)) | K11: =SUMIFS('All Tasks'!$R$2:$R$404,'All Tasks'!$B$2:$B$404,$A11) -> 0 | L11: =COUNTIFS('All Tasks'!$B$2:$B$404,$A11,'All Tasks'!$I$2:$I$404,"Blocked") -> 0 | M11: =IF($H11=0,"",IF($L11>0,$L11&" blocked / "&$K11&" overdue",IF($K11>0,$K11&" overdue task(s)",IF($T11>0,$T11&" roadblock(s) flagged","On track")))) | N11: =IFERROR(minifs('All Tasks'!$L$2:$L$404,'All Tasks'!$B$2:$B$404,$A11,'All Tasks'!$I$2:$I$404,"<>Complete",'All Tasks'!$L$2:$L$404,">"&(TODAY()-1)),"") | O11: =IF($H11=0,"",IF(OR($I11="Blocked",$I11="At Risk"),"R",IF(OR($I11="Complete",$I11="In Progress"),"G","Y"))) | P11: =HYPERLINK("#'Project Review'!C3","Open") -> Open | R11: =COUNTIFS('All Tasks'!$B$2:$B$404,$A11,'All Tasks'!$I$2:$I$404,"Complete") -> 0 | S11: =COUNTIFS('All Tasks'!$B$2:$B$404,$A11,'All Tasks'!$I$2:$I$404,"In Progress")+COUNTIFS('All Tasks'!$B$2:$B$404,$A11,'All Tasks'!$I$2:$I$404,"Waiting on Someone") -> 0 | T11: =SUMIFS('All Tasks'!$V$2:$V$404,'All Tasks'!$B$2:$B$404,$A11) -> 0
A12: P2-2 | B12: 2 – Top-of-Funnel Lead Gen | C12: Reallocate spend toward non-broker sourced channels | D12: Dobelbower | E12: Thoma/Chadwick | F12: Marketing spend allocation is not consistently aligned with lead quality, conversion performance, or long-term scalability objectives. | G12: Short (90) | H12: =COUNTIF('All Tasks'!$B$2:$B$404,$A12) -> 1 | I12: =IF($H12=0,"No Tasks Yet",IF($L12>0,"Blocked",IF($K12>0,"At Risk",IF($R12=$H12,"Complete",IF($S12>0,"In Progress","Not Started"))))) -> Complete | J12: =IF($H12=0,"",ROUND(SUMIFS('All Tasks'!$U$2:$U$404,'All Tasks'!$B$2:$B$404,$A12)/$H12,2)) -> 1 | K12: =SUMIFS('All Tasks'!$R$2:$R$404,'All Tasks'!$B$2:$B$404,$A12) -> 0 | L12: =COUNTIFS('All Tasks'!$B$2:$B$404,$A12,'All Tasks'!$I$2:$I$404,"Blocked") -> 0 | M12: =IF($H12=0,"",IF($L12>0,$L12&" blocked / "&$K12&" overdue",IF($K12>0,$K12&" overdue task(s)",IF($T12>0,$T12&" roadblock(s) flagged","On track")))) -> On track | N12: =IFERROR(minifs('All Tasks'!$L$2:$L$404,'All Tasks'!$B$2:$B$404,$A12,'All Tasks'!$I$2:$I$404,"<>Complete",'All Tasks'!$L$2:$L$404,">"&(TODAY()-1)),"") | O12: =IF($H12=0,"",IF(OR($I12="Blocked",$I12="At Risk"),"R",IF(OR($I12="Complete",$I12="In Progress"),"G","Y"))) -> G | P12: =HYPERLINK("#'Project Review'!C3","Open") -> Open | R12: =COUNTIFS('All Tasks'!$B$2:$B$404,$A12,'All Tasks'!$I$2:$I$404,"Complete") -> 1 | S12: =COUNTIFS('All Tasks'!$B$2:$B$404,$A12,'All Tasks'!$I$2:$I$404,"In Progress")+COUNTIFS('All Tasks'!$B$2:$B$404,$A12,'All Tasks'!$I$2:$I$404,"Waiting on Someone") -> 0 | T12: =SUMIFS('All Tasks'!$V$2:$V$404,'All Tasks'!$B$2:$B$404,$A12) -> 0
A13: P2-3 | B13: 2 – Top-of-Funnel Lead Gen | C13: Build video-first funnel | D13: Dobelbower | E13: M. Anderson/Leal | F13: Video and automation create an opportunity to improve candidate education, consistency, and developer scalability across all brands. | G13: Short (90) | H13: =COUNTIF('All Tasks'!$B$2:$B$404,$A13) -> 2 | I13: =IF($H13=0,"No Tasks Yet",IF($L13>0,"Blocked",IF($K13>0,"At Risk",IF($R13=$H13,"Complete",IF($S13>0,"In Progress","Not Started"))))) -> In Progress | J13: =IF($H13=0,"",ROUND(SUMIFS('All Tasks'!$U$2:$U$404,'All Tasks'!$B$2:$B$404,$A13)/$H13,2)) -> 0.3 | K13: =SUMIFS('All Tasks'!$R$2:$R$404,'All Tasks'!$B$2:$B$404,$A13) -> 0 | L13: =COUNTIFS('All Tasks'!$B$2:$B$404,$A13,'All Tasks'!$I$2:$I$404,"Blocked") -> 0 | M13: =IF($H13=0,"",IF($L13>0,$L13&" blocked / "&$K13&" overdue",IF($K13>0,$K13&" overdue task(s)",IF($T13>0,$T13&" roadblock(s) flagged","On track")))) -> On track | N13: =IFERROR(minifs('All Tasks'!$L$2:$L$404,'All Tasks'!$B$2:$B$404,$A13,'All Tasks'!$I$2:$I$404,"<>Complete",'All Tasks'!$L$2:$L$404,">"&(TODAY()-1)),"") | O13: =IF($H13=0,"",IF(OR($I13="Blocked",$I13="At Risk"),"R",IF(OR($I13="Complete",$I13="In Progress"),"G","Y"))) -> G | P13: =HYPERLINK("#'Project Review'!C3","Open") -> Open | R13: =COUNTIFS('All Tasks'!$B$2:$B$404,$A13,'All Tasks'!$I$2:$I$404,"Complete") -> 0 | S13: =COUNTIFS('All Tasks'!$B$2:$B$404,$A13,'All Tasks'!$I$2:$I$404,"In Progress")+COUNTIFS('All Tasks'!$B$2:$B$404,$A13,'All Tasks'!$I$2:$I$404,"Waiting on Someone") -> 2 | T13: =SUMIFS('All Tasks'!$V$2:$V$404,'All Tasks'!$B$2:$B$404,$A13) -> 0
A14: P2-4 | B14: 2 – Top-of-Funnel Lead Gen | C14: Establish portfolio-level KPIs benchmarked against AFDR ratios | D14: Dobelbower | E14: Mattingly | F14: Portfolio-level KPIs are necessary to properly evaluate marketing efficiency, lead quality, and channel performance across brands. | G14: Mid (180) | H14: =COUNTIF('All Tasks'!$B$2:$B$404,$A14) -> 0 | I14: =IF($H14=0,"No Tasks Yet",IF($L14>0,"Blocked",IF($K14>0,"At Risk",IF($R14=$H14,"Complete",IF($S14>0,"In Progress","Not Started"))))) -> No Tasks Yet | J14: =IF($H14=0,"",ROUND(SUMIFS('All Tasks'!$U$2:$U$404,'All Tasks'!$B$2:$B$404,$A14)/$H14,2)) | K14: =SUMIFS('All Tasks'!$R$2:$R$404,'All Tasks'!$B$2:$B$404,$A14) -> 0 | L14: =COUNTIFS('All Tasks'!$B$2:$B$404,$A14,'All Tasks'!$I$2:$I$404,"Blocked") -> 0 | M14: =IF($H14=0,"",IF($L14>0,$L14&" blocked / "&$K14&" overdue",IF($K14>0,$K14&" overdue task(s)",IF($T14>0,$T14&" roadblock(s) flagged","On track")))) | N14: =IFERROR(minifs('All Tasks'!$L$2:$L$404,'All Tasks'!$B$2:$B$404,$A14,'All Tasks'!$I$2:$I$404,"<>Complete",'All Tasks'!$L$2:$L$404,">"&(TODAY()-1)),"") | O14: =IF($H14=0,"",IF(OR($I14="Blocked",$I14="At Risk"),"R",IF(OR($I14="Complete",$I14="In Progress"),"G","Y"))) | P14: =HYPERLINK("#'Project Review'!C3","Open") -> Open | R14: =COUNTIFS('All Tasks'!$B$2:$B$404,$A14,'All Tasks'!$I$2:$I$404,"Complete") -> 0 | S14: =COUNTIFS('All Tasks'!$B$2:$B$404,$A14,'All Tasks'!$I$2:$I$404,"In Progress")+COUNTIFS('All Tasks'!$B$2:$B$404,$A14,'All Tasks'!$I$2:$I$404,"Waiting on Someone") -> 0 | T14: =SUMIFS('All Tasks'!$V$2:$V$404,'All Tasks'!$B$2:$B$404,$A14) -> 0
A15: P2-5 | B15: 2 – Top-of-Funnel Lead Gen | C15: Eliminate low-quality lead sources | D15: Dobelbower | E15: Chadwick | F15: Certain lead sources currently produce volume without corresponding conversion performance or franchisee quality. | G15: Short (90) | H15: =COUNTIF('All Tasks'!$B$2:$B$404,$A15) -> 0 | I15: =IF($H15=0,"No Tasks Yet",IF($L15>0,"Blocked",IF($K15>0,"At Risk",IF($R15=$H15,"Complete",IF($S15>0,"In Progress","Not Started"))))) -> No Tasks Yet | J15: =IF($H15=0,"",ROUND(SUMIFS('All Tasks'!$U$2:$U$404,'All Tasks'!$B$2:$B$404,$A15)/$H15,2)) | K15: =SUMIFS('All Tasks'!$R$2:$R$404,'All Tasks'!$B$2:$B$404,$A15) -> 0 | L15: =COUNTIFS('All Tasks'!$B$2:$B$404,$A15,'All Tasks'!$I$2:$I$404,"Blocked") -> 0 | M15: =IF($H15=0,"",IF($L15>0,$L15&" blocked / "&$K15&" overdue",IF($K15>0,$K15&" overdue task(s)",IF($T15>0,$T15&" roadblock(s) flagged","On track")))) | N15: =IFERROR(minifs('All Tasks'!$L$2:$L$404,'All Tasks'!$B$2:$B$404,$A15,'All Tasks'!$I$2:$I$404,"<>Complete",'All Tasks'!$L$2:$L$404,">"&(TODAY()-1)),"") | O15: =IF($H15=0,"",IF(OR($I15="Blocked",$I15="At Risk"),"R",IF(OR($I15="Complete",$I15="In Progress"),"G","Y"))) | P15: =HYPERLINK("#'Project Review'!C3","Open") -> Open | R15: =COUNTIFS('All Tasks'!$B$2:$B$404,$A15,'All Tasks'!$I$2:$I$404,"Complete") -> 0 | S15: =COUNTIFS('All Tasks'!$B$2:$B$404,$A15,'All Tasks'!$I$2:$I$404,"In Progress")+COUNTIFS('All Tasks'!$B$2:$B$404,$A15,'All Tasks'!$I$2:$I$404,"Waiting on Someone") -> 0 | T15: =SUMIFS('All Tasks'!$V$2:$V$404,'All Tasks'!$B$2:$B$404,$A15) -> 0
A16: P3-1 | B16: 3 – Broker Channel | C16: Assign MaryFran as broker channel owner | D16: Dobelbower | E16: MF. Anderson | F16: Broker relationships currently lack centralized ownership and consistent management across the portfolio. | G16: Short (90) | H16: =COUNTIF('All Tasks'!$B$2:$B$404,$A16) -> 3 | I16: =IF($H16=0,"No Tasks Yet",IF($L16>0,"Blocked",IF($K16>0,"At Risk",IF($R16=$H16,"Complete",IF($S16>0,"In Progress","Not Started"))))) -> Blocked | J16: =IF($H16=0,"",ROUND(SUMIFS('All Tasks'!$U$2:$U$404,'All Tasks'!$B$2:$B$404,$A16)/$H16,2)) -> 0.13 | K16: =SUMIFS('All Tasks'!$R$2:$R$404,'All Tasks'!$B$2:$B$404,$A16) -> 0 | L16: =COUNTIFS('All Tasks'!$B$2:$B$404,$A16,'All Tasks'!$I$2:$I$404,"Blocked") -> 1 | M16: =IF($H16=0,"",IF($L16>0,$L16&" blocked / "&$K16&" overdue",IF($K16>0,$K16&" overdue task(s)",IF($T16>0,$T16&" roadblock(s) flagged","On track")))) -> 1 blocked / 0 overdue | N16: =IFERROR(minifs('All Tasks'!$L$2:$L$404,'All Tasks'!$B$2:$B$404,$A16,'All Tasks'!$I$2:$I$404,"<>Complete",'All Tasks'!$L$2:$L$404,">"&(TODAY()-1)),"") | O16: =IF($H16=0,"",IF(OR($I16="Blocked",$I16="At Risk"),"R",IF(OR($I16="Complete",$I16="In Progress"),"G","Y"))) -> R | P16: =HYPERLINK("#'Project Review'!C3","Open") -> Open | R16: =COUNTIFS('All Tasks'!$B$2:$B$404,$A16,'All Tasks'!$I$2:$I$404,"Complete") -> 0 | S16: =COUNTIFS('All Tasks'!$B$2:$B$404,$A16,'All Tasks'!$I$2:$I$404,"In Progress")+COUNTIFS('All Tasks'!$B$2:$B$404,$A16,'All Tasks'!$I$2:$I$404,"Waiting on Someone") -> 1 | T16: =SUMIFS('All Tasks'!$V$2:$V$404,'All Tasks'!$B$2:$B$404,$A16) -> 1
... A19: P3-4 | B19: 3 – Broker Channel | C19: Enforce speed-to-lead SLAs | D19: Dobelbower | E19: MF. Anderson | F19: Response speed remains one of the largest drivers of broker lead conversion and candidate engagement. | G19: Short (90) | H19: =COUNTIF('All Tasks'!$B$2:$B$404,$A19) -> 1 | I19: =IF($H19=0,"No Tasks Yet",IF($L19>0,"Blocked",IF($K19>0,"At Risk",IF($R19=$H19,"Complete",IF($S19>0,"In Progress","Not Started"))))) -> In Progress | J19: =IF($H19=0,"",ROUND(SUMIFS('All Tasks'!$U$2:$U$404,'All Tasks'!$B$2:$B$404,$A19)/$H19,2)) -> 0.2 | K19: =SUMIFS('All Tasks'!$R$2:$R$404,'All Tasks'!$B$2:$B$404,$A19) -> 0 | L19: =COUNTIFS('All Tasks'!$B$2:$B$404,$A19,'All Tasks'!$I$2:$I$404,"Blocked") -> 0 | M19: =IF($H19=0,"",IF($L19>0,$L19&" blocked / "&$K19&" overdue",IF($K19>0,$K19&" overdue task(s)",IF($T19>0,$T19&" roadblock(s) flagged","On track")))) -> On track | N19: =IFERROR(minifs('All Tasks'!$L$2:$L$404,'All Tasks'!$B$2:$B$404,$A19,'All Tasks'!$I$2:$I$404,"<>Complete",'All Tasks'!$L$2:$L$404,">"&(TODAY()-1)),"") | O19: =IF($H19=0,"",IF(OR($I19="Blocked",$I19="At Risk"),"R",IF(OR($I19="Complete",$I19="In Progress"),"G","Y"))) -> G | P19: =HYPERLINK("#'Project Review'!C3","Open") -> Open | R19: =COUNTIFS('All Tasks'!$B$2:$B$404,$A19,'All Tasks'!$I$2:$I$404,"Complete") -> 0 | S19: =COUNTIFS('All Tasks'!$B$2:$B$404,$A19,'All Tasks'!$I$2:$I$404,"In Progress")+COUNTIFS('All Tasks'!$B$2:$B$404,$A19,'All Tasks'!$I$2:$I$404,"Waiting on Someone") -> 1 | T19: =SUMIFS('All Tasks'!$V$2:$V$404,'All Tasks'!$B$2:$B$404,$A19) -> 0
A20: P3-5 | B20: 3 – Broker Channel | C20: Segment Brokers into Tier 1/Tier 2/ Tier 3 | D20: Dobelbower | E20: MF. Anderson | F20: Not all broker relationships generate equal value, requiring prioritization based on production and lead quality. | H20: =COUNTIF('All Tasks'!$B$2:$B$404,$A20) -> 0 | I20: =IF($H20=0,"No Tasks Yet",IF($L20>0,"Blocked",IF($K20>0,"At Risk",IF($R20=$H20,"Complete",IF($S20>0,"In Progress","Not Started"))))) -> No Tasks Yet | J20: =IF($H20=0,"",ROUND(SUMIFS('All Tasks'!$U$2:$U$404,'All Tasks'!$B$2:$B$404,$A20)/$H20,2)) | K20: =SUMIFS('All Tasks'!$R$2:$R$404,'All Tasks'!$B$2:$B$404,$A20) -> 0 | L20: =COUNTIFS('All Tasks'!$B$2:$B$404,$A20,'All Tasks'!$I$2:$I$404,"Blocked") -> 0 | M20: =IF($H20=0,"",IF($L20>0,$L20&" blocked / "&$K20&" overdue",IF($K20>0,$K20&" overdue task(s)",IF($T20>0,$T20&" roadblock(s) flagged","On track")))) | N20: =IFERROR(minifs('All Tasks'!$L$2:$L$404,'All Tasks'!$B$2:$B$404,$A20,'All Tasks'!$I$2:$I$404,"<>Complete",'All Tasks'!$L$2:$L$404,">"&(TODAY()-1)),"") | O20: =IF($H20=0,"",IF(OR($I20="Blocked",$I20="At Risk"),"R",IF(OR($I20="Complete",$I20="In Progress"),"G","Y"))) | P20: =HYPERLINK("#'Project Review'!C3","Open") -> Open | R20: =COUNTIFS('All Tasks'!$B$2:$B$404,$A20,'All Tasks'!$I$2:$I$404,"Complete") -> 0 | S20: =COUNTIFS('All Tasks'!$B$2:$B$404,$A20,'All Tasks'!$I$2:$I$404,"In Progress")+COUNTIFS('All Tasks'!$B$2:$B$404,$A20,'All Tasks'!$I$2:$I$404,"Waiting on Someone") -> 0 | T20: =SUMIFS('All Tasks'!$V$2:$V$404,'All Tasks'!$B$2:$B$404,$A20) -> 0
A21: P3-6 | B21: 3 – Broker Channel | C21: Introduce performance-based lead weighting | D21: Dobelbower | E21: Mattingly/Ruhlig | F21: Lead distribution should reward execution and conversion performance while maintaining equitable opportunity across the team. | H21: =COUNTIF('All Tasks'!$B$2:$B$404,$A21) -> 0 | I21: =IF($H21=0,"No Tasks Yet",IF($L21>0,"Blocked",IF($K21>0,"At Risk",IF($R21=$H21,"Complete",IF($S21>0,"In Progress","Not Started"))))) -> No Tasks Yet | J21: =IF($H21=0,"",ROUND(SUMIFS('All Tasks'!$U$2:$U$404,'All Tasks'!$B$2:$B$404,$A21)/$H21,2)) | K21: =SUMIFS('All Tasks'!$R$2:$R$404,'All Tasks'!$B$2:$B$404,$A21) -> 0 | L21: =COUNTIFS('All Tasks'!$B$2:$B$404,$A21,'All Tasks'!$I$2:$I$404,"Blocked") -> 0 | M21: =IF($H21=0,"",IF($L21>0,$L21&" blocked / "&$K21&" overdue",IF($K21>0,$K21&" overdue task(s)",IF($T21>0,$T21&" roadblock(s) flagged","On track")))) | N21: =IFERROR(minifs('All Tasks'!$L$2:$L$404,'All Tasks'!$B$2:$B$404,$A21,'All Tasks'!$I$2:$I$404,"<>Complete",'All Tasks'!$L$2:$L$404,">"&(TODAY()-1)),"") | O21: =IF($H21=0,"",IF(OR($I21="Blocked",$I21="At Risk"),"R",IF(OR($I21="Complete",$I21="In Progress"),"G","Y"))) | P21: =HYPERLINK("#'Project Review'!C3","Open") -> Open | R21: =COUNTIFS('All Tasks'!$B$2:$B$404,$A21,'All Tasks'!$I$2:$I$404,"Complete") -> 0 | S21: =COUNTIFS('All Tasks'!$B$2:$B$404,$A21,'All Tasks'!$I$2:$I$404,"In Progress")+COUNTIFS('All Tasks'!$B$2:$B$404,$A21,'All Tasks'!$I$2:$I$404,"Waiting on Someone") -> 0 | T21: =SUMIFS('All Tasks'!$V$2:$V$404,'All Tasks'!$B$2:$B$404,$A21) -> 0
A22: P3-7 | B22: 3 – Broker Channel | C22: Build weekly broker channel performance reporting | D22: Dobelbower | E22: Mattingly/Ruhlig | F22: Broker performance visibility is currently limited, making it difficult to optimize relationships and conversion performance. | G22: Short (90) | H22: =COUNTIF('All Tasks'!$B$2:$B$404,$A22) -> 0 | I22: =IF($H22=0,"No Tasks Yet",IF($L22>0,"Blocked",IF($K22>0,"At Risk",IF($R22=$H22,"Complete",IF($S22>0,"In Progress","Not Started"))))) -> No Tasks Yet | J22: =IF($H22=0,"",ROUND(SUMIFS('All Tasks'!$U$2:$U$404,'All Tasks'!$B$2:$B$404,$A22)/$H22,2)) | K22: =SUMIFS('All Tasks'!$R$2:$R$404,'All Tasks'!$B$2:$B$404,$A22) -> 0 | L22: =COUNTIFS('All Tasks'!$B$2:$B$404,$A22,'All Tasks'!$I$2:$I$404,"Blocked") -> 0 | M22: =IF($H22=0,"",IF($L22>0,$L22&" blocked / "&$K22&" overdue",IF($K22>0,$K22&" overdue task(s)",IF($T22>0,$T22&" roadblock(s) flagged","On track")))) | N22: =IFERROR(minifs('All Tasks'!$L$2:$L$404,'All Tasks'!$B$2:$B$404,$A22,'All Tasks'!$I$2:$I$404,"<>Complete",'All Tasks'!$L$2:$L$404,">"&(TODAY()-1)),"") | O22: =IF($H22=0,"",IF(OR($I22="Blocked",$I22="At Risk"),"R",IF(OR($I22="Complete",$I22="In Progress"),"G","Y"))) | P22: =HYPERLINK("#'Project Review'!C3","Open") -> Open | R22: =COUNTIFS('All Tasks'!$B$2:$B$404,$A22,'All Tasks'!$I$2:$I$404,"Complete") -> 0 | S22: =COUNTIFS('All Tasks'!$B$2:$B$404,$A22,'All Tasks'!$I$2:$I$404,"In Progress")+COUNTIFS('All Tasks'!$B$2:$B$404,$A22,'All Tasks'!$I$2:$I$404,"Waiting on Someone") -> 0 | T22: =SUMIFS('All Tasks'!$V$2:$V$404,'All Tasks'!$B$2:$B$404,$A22) -> 0
A23: P4-1 | B23: 4 – Portfolio Brand Strategy | C23: Position The Seals as a low-cost, high-whitespace growth brand | D23: Dobelbower | E23: Anderson/Chadwick | F23: The Seals presents an opportunity for accelerated unit growth due to low investment requirements, recurring revenue characteristics, and significant whitespace availability. | G23: Short (90) | H23: =COUNTIF('All Tasks'!$B$2:$B$404,$A23) -> 0 | I23: =IF($H23=0,"No Tasks Yet",IF($L23>0,"Blocked",IF($K23>0,"At Risk",IF($R23=$H23,"Complete",IF($S23>0,"In Progress","Not Started"))))) -> No Tasks Yet | J23: =IF($H23=0,"",ROUND(SUMIFS('All Tasks'!$U$2:$U$404,'All Tasks'!$B$2:$B$404,$A23)/$H23,2)) | K23: =SUMIFS('All Tasks'!$R$2:$R$404,'All Tasks'!$B$2:$B$404,$A23) -> 0 | L23: =COUNTIFS('All Tasks'!$B$2:$B$404,$A23,'All Tasks'!$I$2:$I$404,"Blocked") -> 0 | M23: =IF($H23=0,"",IF($L23>0,$L23&" blocked / "&$K23&" overdue",IF($K23>0,$K23&" overdue task(s)",IF($T23>0,$T23&" roadblock(s) flagged","On track")))) | N23: =IFERROR(minifs('All Tasks'!$L$2:$L$404,'All Tasks'!$B$2:$B$404,$A23,'All Tasks'!$I$2:$I$404,"<>Complete",'All Tasks'!$L$2:$L$404,">"&(TODAY()-1)),"") | O23: =IF($H23=0,"",IF(OR($I23="Blocked",$I23="At Risk"),"R",IF(OR($I23="Complete",$I23="In Progress"),"G","Y"))) | P23: =HYPERLINK("#'Project Review'!C3","Open") -> Open | R23: =COUNTIFS('All Tasks'!$B$2:$B$404,$A23,'All Tasks'!$I$2:$I$404,"Complete") -> 0 | S23: =COUNTIFS('All Tasks'!$B$2:$B$404,$A23,'All Tasks'!$I$2:$I$404,"In Progress")+COUNTIFS('All Tasks'!$B$2:$B$404,$A23,'All Tasks'!$I$2:$I$404,"Waiting on Someone") -> 0 | T23: =SUMIFS('All Tasks'!$V$2:$V$404,'All Tasks'!$B$2:$B$404,$A23) -> 0
A24: P4-2 | B24: 4 – Portfolio Brand Strategy | C24: Position 1-Tom as a flagship growth brand | D24: Dobelbower | E24: Anderson/Chadwick | F24: 1-Tom possesses strong branding, broad market appeal, and favorable long-term scalability characteristics. | G24: Short (90) | H24: =COUNTIF('All Tasks'!$B$2:$B$404,$A24) -> 0 | I24: =IF($H24=0,"No Tasks Yet",IF($L24>0,"Blocked",IF($K24>0,"At Risk",IF($R24=$H24,"Complete",IF($S24>0,"In Progress","Not Started"))))) -> No Tasks Yet | J24: =IF($H24=0,"",ROUND(SUMIFS('All Tasks'!$U$2:$U$404,'All Tasks'!$B$2:$B$404,$A24)/$H24,2)) | K24: =SUMIFS('All Tasks'!$R$2:$R$404,'All Tasks'!$B$2:$B$404,$A24) -> 0 | L24: =COUNTIFS('All Tasks'!$B$2:$B$404,$A24,'All Tasks'!$I$2:$I$404,"Blocked") -> 0 | M24: =IF($H24=0,"",IF($L24>0,$L24&" blocked / "&$K24&" overdue",IF($K24>0,$K24&" overdue task(s)",IF($T24>0,$T24&" roadblock(s) flagged","On track")))) | N24: =IFERROR(minifs('All Tasks'!$L$2:$L$404,'All Tasks'!$B$2:$B$404,$A24,'All Tasks'!$I$2:$I$404,"<>Complete",'All Tasks'!$L$2:$L$404,">"&(TODAY()-1)),"") | O24: =IF($H24=0,"",IF(OR($I24="Blocked",$I24="At Risk"),"R",IF(OR($I24="Complete",$I24="In Progress"),"G","Y"))) | P24: =HYPERLINK("#'Project Review'!C3","Open") -> Open | R24: =COUNTIFS('All Tasks'!$B$2:$B$404,$A24,'All Tasks'!$I$2:$I$404,"Complete") -> 0 | S24: =COUNTIFS('All Tasks'!$B$2:$B$404,$A24,'All Tasks'!$I$2:$I$404,"In Progress")+COUNTIFS('All Tasks'!$B$2:$B$404,$A24,'All Tasks'!$I$2:$I$404,"Waiting on Someone") -> 0 | T24: =SUMIFS('All Tasks'!$V$2:$V$404,'All Tasks'!$B$2:$B$404,$A24) -> 0
A25: P4-3 | B25: 4 – Portfolio Brand Strategy | C25: Align Kitchen Guard growth strategy with Strategic Accounts initiatives | D25: Dobelbower | E25: Hatcher | F25: Kitchen Guard’s compliance-driven recurring revenue model aligns well with enterprise and Strategic Account positioning opportunities. | G25: Long (270) | H25: =COUNTIF('All Tasks'!$B$2:$B$404,$A25) -> 0 | I25: =IF($H25=0,"No Tasks Yet",IF($L25>0,"Blocked",IF($K25>0,"At Risk",IF($R25=$H25,"Complete",IF($S25>0,"In Progress","Not Started"))))) -> No Tasks Yet | J25: =IF($H25=0,"",ROUND(SUMIFS('All Tasks'!$U$2:$U$404,'All Tasks'!$B$2:$B$404,$A25)/$H25,2)) | K25: =SUMIFS('All Tasks'!$R$2:$R$404,'All Tasks'!$B$2:$B$404,$A25) -> 0 | L25: =COUNTIFS('All Tasks'!$B$2:$B$404,$A25,'All Tasks'!$I$2:$I$404,"Blocked") -> 0 | M25: =IF($H25=0,"",IF($L25>0,$L25&" blocked / "&$K25&" overdue",IF($K25>0,$K25&" overdue task(s)",IF($T25>0,$T25&" roadblock(s) flagged","On track")))) | N25: =IFERROR(minifs('All Tasks'!$L$2:$L$404,'All Tasks'!$B$2:$B$404,$A25,'All Tasks'!$I$2:$I$404,"<>Complete",'All Tasks'!$L$2:$L$404,">"&(TODAY()-1)),"") | O25: =IF($H25=0,"",IF(OR($I25="Blocked",$I25="At Risk"),"R",IF(OR($I25="Complete",$I25="In Progress"),"G","Y"))) | P25: =HYPERLINK("#'Project Review'!C3","Open") -> Open | R25: =COUNTIFS('All Tasks'!$B$2:$B$404,$A25,'All Tasks'!$I$2:$I$404,"Complete") -> 0 | S25: =COUNTIFS('All Tasks'!$B$2:$B$404,$A25,'All Tasks'!$I$2:$I$404,"In Progress")+COUNTIFS('All Tasks'!$B$2:$B$404,$A25,'All Tasks'!$I$2:$I$404,"Waiting on Someone") -> 0 | T25: =SUMIFS('All Tasks'!$V$2:$V$404,'All Tasks'!$B$2:$B$404,$A25) -> 0
A26: P4-4 | B26: 4 – Portfolio Brand Strategy | C26: Reposition Prism as a multi-service platform opportunity | D26: Dobelbower | E26: Anderson/Chadwick | F26: Prism’s multi-service structure creates an opportunity to increase average deal size and long-term franchisee value. | G26: Short (90) | H26: =COUNTIF('All Tasks'!$B$2:$B$404,$A26) -> 0 | I26: =IF($H26=0,"No Tasks Yet",IF($L26>0,"Blocked",IF($K26>0,"At Risk",IF($R26=$H26,"Complete",IF($S26>0,"In Progress","Not Started"))))) -> No Tasks Yet | J26: =IF($H26=0,"",ROUND(SUMIFS('All Tasks'!$U$2:$U$404,'All Tasks'!$B$2:$B$404,$A26)/$H26,2)) | K26: =SUMIFS('All Tasks'!$R$2:$R$404,'All Tasks'!$B$2:$B$404,$A26) -> 0 | L26: =COUNTIFS('All Tasks'!$B$2:$B$404,$A26,'All Tasks'!$I$2:$I$404,"Blocked") -> 0 | M26: =IF($H26=0,"",IF($L26>0,$L26&" blocked / "&$K26&" overdue",IF($K26>0,$K26&" overdue task(s)",IF($T26>0,$T26&" roadblock(s) flagged","On track")))) | N26: =IFERROR(minifs('All Tasks'!$L$2:$L$404,'All Tasks'!$B$2:$B$404,$A26,'All Tasks'!$I$2:$I$404,"<>Complete",'All Tasks'!$L$2:$L$404,">"&(TODAY()-1)),"") | O26: =IF($H26=0,"",IF(OR($I26="Blocked",$I26="At Risk"),"R",IF(OR($I26="Complete",$I26="In Progress"),"G","Y"))) | P26: =HYPERLINK("#'Project Review'!C3","Open") -> Open | R26: =COUNTIFS('All Tasks'!$B$2:$B$404,$A26,'All Tasks'!$I$2:$I$404,"Complete") -> 0 | S26: =COUNTIFS('All Tasks'!$B$2:$B$404,$A26,'All Tasks'!$I$2:$I$404,"In Progress")+COUNTIFS('All Tasks'!$B$2:$B$404,$A26,'All Tasks'!$I$2:$I$404,"Waiting on Someone") -> 0 | T26: =SUMIFS('All Tasks'!$V$2:$V$404,'All Tasks'!$B$2:$B$404,$A26) -> 0
A27: P4-5 | B27: 4 – Portfolio Brand Strategy | C27: Maintain stable, quality-focused growth for U.S. Lawns | D27: Dobelbower | E27: Steeves | F27: U.S. Lawns serves as a mature and stable portfolio brand with strong recognition and operational consistency. | G27: Short (90) | H27: =COUNTIF('All Tasks'!$B$2:$B$404,$A27) -> 0 | I27: =IF($H27=0,"No Tasks Yet",IF($L27>0,"Blocked",IF($K27>0,"At Risk",IF($R27=$H27,"Complete",IF($S27>0,"In Progress","Not Started"))))) -> No Tasks Yet | J27: =IF($H27=0,"",ROUND(SUMIFS('All Tasks'!$U$2:$U$404,'All Tasks'!$B$2:$B$404,$A27)/$H27,2)) | K27: =SUMIFS('All Tasks'!$R$2:$R$404,'All Tasks'!$B$2:$B$404,$A27) -> 0 | L27: =COUNTIFS('All Tasks'!$B$2:$B$404,$A27,'All Tasks'!$I$2:$I$404,"Blocked") -> 0 | M27: =IF($H27=0,"",IF($L27>0,$L27&" blocked / "&$K27&" overdue",IF($K27>0,$K27&" overdue task(s)",IF($T27>0,$T27&" roadblock(s) flagged","On track")))) | N27: =IFERROR(minifs('All Tasks'!$L$2:$L$404,'All Tasks'!$B$2:$B$404,$A27,'All Tasks'!$I$2:$I$404,"<>Complete",'All Tasks'!$L$2:$L$404,">"&(TODAY()-1)),"") | O27: =IF($H27=0,"",IF(OR($I27="Blocked",$I27="At Risk"),"R",IF(OR($I27="Complete",$I27="In Progress"),"G","Y"))) | P27: =HYPERLINK("#'Project Review'!C3","Open") -> Open | R27: =COUNTIFS('All Tasks'!$B$2:$B$404,$A27,'All Tasks'!$I$2:$I$404,"Complete") -> 0 | S27: =COUNTIFS('All Tasks'!$B$2:$B$404,$A27,'All Tasks'!$I$2:$I$404,"In Progress")+COUNTIFS('All Tasks'!$B$2:$B$404,$A27,'All Tasks'!$I$2:$I$404,"Waiting on Someone") -> 0 | T27: =SUMIFS('All Tasks'!$V$2:$V$404,'All Tasks'!$B$2:$B$404,$A27) -> 0
A28: P4-6 | B28: 4 – Portfolio Brand Strategy | C28: Utilize Clintar as a selective strategic growth vehicle | D28: Dobelbower | E28: Motyka | F28: Clintar should be positioned toward experienced operators and strategic opportunities rather than high-volume franchise sales efforts. | G28: Mid (180) | H28: =COUNTIF('All Tasks'!$B$2:$B$404,$A28) -> 1 | I28: =IF($H28=0,"No Tasks Yet",IF($L28>0,"Blocked",IF($K28>0,"At Risk",IF($R28=$H28,"Complete",IF($S28>0,"In Progress","Not Started"))))) -> In Progress | J28: =IF($H28=0,"",ROUND(SUMIFS('All Tasks'!$U$2:$U$404,'All Tasks'!$B$2:$B$404,$A28)/$H28,2)) -> 0.3 | K28: =SUMIFS('All Tasks'!$R$2:$R$404,'All Tasks'!$B$2:$B$404,$A28) -> 0 | L28: =COUNTIFS('All Tasks'!$B$2:$B$404,$A28,'All Tasks'!$I$2:$I$404,"Blocked") -> 0 | M28: =IF($H28=0,"",IF($L28>0,$L28&" blocked / "&$K28&" overdue",IF($K28>0,$K28&" overdue task(s)",IF($T28>0,$T28&" roadblock(s) flagged","On track")))) -> On track | N28: =IFERROR(minifs('All Tasks'!$L$2:$L$404,'All Tasks'!$B$2:$B$404,$A28,'All Tasks'!$I$2:$I$404,"<>Complete",'All Tasks'!$L$2:$L$404,">"&(TODAY()-1)),"") | O28: =IF($H28=0,"",IF(OR($I28="Blocked",$I28="At Risk"),"R",IF(OR($I28="Complete",$I28="In Progress"),"G","Y"))) -> G | P28: =HYPERLINK("#'Project Review'!C3","Open") -> Open | R28: =COUNTIFS('All Tasks'!$B$2:$B$404,$A28,'All Tasks'!$I$2:$I$404,"Complete") -> 0 | S28: =COUNTIFS('All Tasks'!$B$2:$B$404,$A28,'All Tasks'!$I$2:$I$404,"In Progress")+COUNTIFS('All Tasks'!$B$2:$B$404,$A28,'All Tasks'!$I$2:$I$404,"Waiting on Someone") -> 1 | T28: =SUMIFS('All Tasks'!$V$2:$V$404,'All Tasks'!$B$2:$B$404,$A28) -> 0
A29: P4-7 | B29: 4 – Portfolio Brand Strategy | C29: Rebuild validation and franchisee confidence within MilliCare | D29: Dobelbower | E29: Griffith/Weaver | F29: Long-term MilliCare growth requires improvement in franchisee sentiment, validation consistency, and economic confidence. | G29: Long (270) | H29: =COUNTIF('All Tasks'!$B$2:$B$404,$A29) -> 1 | I29: =IF($H29=0,"No Tasks Yet",IF($L29>0,"Blocked",IF($K29>0,"At Risk",IF($R29=$H29,"Complete",IF($S29>0,"In Progress","Not Started"))))) -> In Progress | J29: =IF($H29=0,"",ROUND(SUMIFS('All Tasks'!$U$2:$U$404,'All Tasks'!$B$2:$B$404,$A29)/$H29,2)) -> 0.2 | K29: =SUMIFS('All Tasks'!$R$2:$R$404,'All Tasks'!$B$2:$B$404,$A29) -> 0 | L29: =COUNTIFS('All Tasks'!$B$2:$B$404,$A29,'All Tasks'!$I$2:$I$404,"Blocked") -> 0 | M29: =IF($H29=0,"",IF($L29>0,$L29&" blocked / "&$K29&" overdue",IF($K29>0,$K29&" overdue task(s)",IF($T29>0,$T29&" roadblock(s) flagged","On track")))) -> 1 roadblock(s) flagged | N29: =IFERROR(minifs('All Tasks'!$L$2:$L$404,'All Tasks'!$B$2:$B$404,$A29,'All Tasks'!$I$2:$I$404,"<>Complete",'All Tasks'!$L$2:$L$404,">"&(TODAY()-1)),"") | O29: =IF($H29=0,"",IF(OR($I29="Blocked",$I29="At Risk"),"R",IF(OR($I29="Complete",$I29="In Progress"),"G","Y"))) -> G | P29: =HYPERLINK("#'Project Review'!C3","Open") -> Open | R29: =COUNTIFS('All Tasks'!$B$2:$B$404,$A29,'All Tasks'!$I$2:$I$404,"Complete") -> 0 | S29: =COUNTIFS('All Tasks'!$B$2:$B$404,$A29,'All Tasks'!$I$2:$I$404,"In Progress")+COUNTIFS('All Tasks'!$B$2:$B$404,$A29,'All Tasks'!$I$2:$I$404,"Waiting on Someone") -> 1 | T29: =SUMIFS('All Tasks'!$V$2:$V$404,'All Tasks'!$B$2:$B$404,$A29) -> 1
